Workbook

Sheet Removed Test Campaigns
A1: MIN | G1: =MIN(G$7:G$169) -> 0 | H1: =MIN(H$7:H$169) -> 2 | I1: =MIN(I$7:I$169) -> 0 | J1: =MIN(J$7:J$169) -> 0 | K1: =MIN(K$7:K$169) -> 0 | L1: =MIN(L$7:L$169) -> 0 | M1: =MIN(M$7:M$169) -> 0 | N1: =MIN(N$7:N$169) -> 0 | ... P1: =MIN(P$7:P$169) -> 1
A2: MEAN | G2: =AVERAGE(G$7:G$169) -> 126951.25 | H2: =AVERAGE(H$7:H$169) -> 120.7546 | I2: =AVERAGE(I$7:I$169) -> 1765.1689 | J2: =AVERAGE(J$7:J$169) -> 249.69325 | K2: =AVERAGE(K$7:K$169) -> 2.3873461 | L2: =AVERAGE(L$7:L$169) -> 72.079755 | M2: =AVERAGE(M$7:M$169) -> 0.10009818 | N2: =AVERAGE(N$7:N$169) -> 1126.0552 | ... P2: =AVERAGE(P$7:P$169) -> 5.5153374
A3: MEDIAN | G3: =MEDIAN(G$7:G$169) -> 37835 | H3: =MEDIAN(H$7:H$169) -> 20 | I3: =MEDIAN(I$7:I$169) -> 1589.8036 | J3: =MEDIAN(J$7:J$169) -> 13 | K3: =MEDIAN(K$7:K$169) -> 1.2928571 | L3: =MEDIAN(L$7:L$169) -> 5 | M3: =MEDIAN(M$7:M$169) -> 0.0027861251 | N3: =MEDIAN(N$7:N$169) -> 199 | ... P3: =MEDIAN(P$7:P$169) -> 2
A4: MODE | G4: =MODE(G$7:G$169) -> 0 | H4: =MODE(H$7:H$169) -> 2 | I4: =MODE(I$7:I$169) -> 0 | J4: =MODE(J$7:J$169) -> 0 | K4: =MODE(K$7:K$169) -> 0 | L4: =MODE(L$7:L$169) -> 0 | M4: =MODE(M$7:M$169) -> 0 | N4: =MODE(N$7:N$169) -> 0 | ... P4: =MODE(P$7:P$169) -> 1
A5: MAX | G5: =MAX(G$7:G$169) -> 4785277 | H5: =MAX(H$7:H$169) -> 2932 | I5: =MAX(I$7:I$169) -> 8837.5714 | J5: =MAX(J$7:J$169) -> 12107 | K5: =MAX(K$7:K$169) -> 41.545455 | L5: =MAX(L$7:L$169) -> 4003 | M5: =MAX(M$7:M$169) -> 4.8057178 | N5: =MAX(N$7:N$169) -> 20196 | ... P5: =MAX(P$7:P$169) -> 185
A6: f | B6: Company | C6: Agency | D6: campaign_id | E6: campaign_title | F6: Paid or not | G6: potential reach | H6: total_share | I6: Reach per Share | J6: total_clicks | K6: Clicks per Share | L6: total_comments | M6: Comments Per Share | N6: total_likes | O6: Likes Per Share | P6: total_posts | Q6: Reshare | R6: Registrations | S6: EMV | T6: Direct Savings | U6: Total Return | V6: ROI (in X) | W6: Registration/Share
A7: Abhishek Ahuja | B7: Autodesk | D7: 343 | E7: Social Champ Contest | F7: Paid | G7: 90247 | H7: 81 | I7: 1114.1605 | J7: 150 | K7: 1.8518519 | L7: 6 | M7: 0.0053852206 | N7: 623 | O7: 0.5591654 | P7: 8 | Q7: =H7*2 -> 162 | R7: =J7*Assumptions!$E$19 -> 39 | S7: =G7*Assumptions!$E$10*Assumptions!$E$6+J7*Assumptions!$E$7+M7*Assumptions!$E$13*Assumptions!$E$6+N7*Assumptions!$E$12*Assumptions!$E$6+Q7*Assumptions!$E$15*Assumptions!$E$6 -> 73715.707 | T7: =R7*Assumptions!$E$20-H7*Assumptions!$E$21 -> 22800 | U7: =T7+S7 -> 96515.707 | V7: =U7/H7/Assumptions!$E$21 -> 5.9577597 | W7: =R7/H7 -> 0.48148148
A8: Abhishek Sharma | B8: MongoDB | D8: 231 | E8: MongoDB Local BLR | F8: Paid | G8: 916839 | H8: 824 | I8: 1112.6687 | J8: 4225 | K8: 5.1274272 | L8: 263 | M8: 0.23636865 | N8: 18752 | O8: 16.853175 | P8: 5 | Q8: =H8*2 -> 1648 | R8: =J8*Assumptions!$E$19 -> 1098.5 | S8: =G8*Assumptions!$E$10*Assumptions!$E$6+J8*Assumptions!$E$7+M8*Assumptions!$E$13*Assumptions!$E$6+N8*Assumptions!$E$12*Assumptions!$E$6+Q8*Assumptions!$E$15*Assumptions!$E$6 -> 1859114.3 | T8: =R8*Assumptions!$E$20-H8*Assumptions!$E$21 -> 933700 | U8: =T8+S8 -> 2792814.3 | V8: =U8/H8/Assumptions!$E$21 -> 16.946688 | W8: =R8/H8 -> 1.3331311
A9: Abhishek Sharma | B9: MongoDB | D9: 237 | E9: MongoDB Local Mumbai | F9: Paid | G9: 429645 | H9: 412 | I9: 1042.8277 | J9: 0 | K9: 0 | L9: 200 | M9: 0.19178624 | N9: 10454 | O9: 10.024667 | P9: 5 | Q9: =H9*2 -> 824 | R9: =J9*Assumptions!$E$19 -> 0 | S9: =G9*Assumptions!$E$10*Assumptions!$E$6+J9*Assumptions!$E$7+M9*Assumptions!$E$13*Assumptions!$E$6+N9*Assumptions!$E$12*Assumptions!$E$6+Q9*Assumptions!$E$15*Assumptions!$E$6 -> 329412.4 | T9: =R9*Assumptions!$E$20-H9*Assumptions!$E$21 -> -82400 | U9: =T9+S9 -> 247012.4 | V9: =U9/H9/Assumptions!$E$21 -> 2.9977233 | W9: =R9/H9 -> 0
A10: Abhishek Sharma | B10: MongoDB | D10: 232 | E10: MongoDB Local Delhi | F10: Paid | G10: 623203 | H10: 392 | I10: 1589.8036 | J10: 0 | K10: 0 | L10: 236 | M10: 0.14844601 | N10: 9730 | O10: 6.120253 | P10: 5 | Q10: =H10*2 -> 784 | R10: =J10*Assumptions!$E$19 -> 0 | S10: =G10*Assumptions!$E$10*Assumptions!$E$6+J10*Assumptions!$E$7+M10*Assumptions!$E$13*Assumptions!$E$6+N10*Assumptions!$E$12*Assumptions!$E$6+Q10*Assumptions!$E$15*Assumptions!$E$6 -> 321407.61 | T10: =R10*Assumptions!$E$20-H10*Assumptions!$E$21 -> -78400 | U10: =T10+S10 -> 243007.61 | V10: =U10/H10/Assumptions!$E$21 -> 3.0995869 | W10: =R10/H10 -> 0
A11: Abhishek Sharma | B11: MongoDB | D11: 243 | E11: MongoDB Local London | F11: Paid | G11: 42431 | H11: 117 | I11: 362.65812 | J11: 0 | K11: 0 | L11: 32 | M11: 0.088237374 | N11: 1500 | O11: 4.1361269 | P11: 9 | Q11: =H11*2 -> 234 | R11: =J11*Assumptions!$E$19 -> 0 | S11: =G11*Assumptions!$E$10*Assumptions!$E$6+J11*Assumptions!$E$7+M11*Assumptions!$E$13*Assumptions!$E$6+N11*Assumptions!$E$12*Assumptions!$E$6+Q11*Assumptions!$E$15*Assumptions!$E$6 -> 51856.349 | T11: =R11*Assumptions!$E$20-H11*Assumptions!$E$21 -> -23400 | U11: =T11+S11 -> 28456.349 | V11: =U11/H11/Assumptions!$E$21 -> 1.2160833 | W11: =R11/H11 -> 0
A12: Abhishek Sharma | B12: MongoDB | D12: 230 | E12: Dry Run | F12: Trial | G12: 966 | H12: 2 | I12: 483 | J12: 0 | K12: 0 | L12: 0 | M12: 0 | N12: 0 | O12: 0 | P12: 1 | Q12: =H12*2 -> 4 | R12: =J12*Assumptions!$E$19 -> 0 | S12: =G12*Assumptions!$E$10*Assumptions!$E$6+J12*Assumptions!$E$7+M12*Assumptions!$E$13*Assumptions!$E$6+N12*Assumptions!$E$12*Assumptions!$E$6+Q12*Assumptions!$E$15*Assumptions!$E$6 -> 260.375 | T12: =R12*Assumptions!$E$20-H12*Assumptions!$E$21 -> -400 | U12: =T12+S12 -> -139.625 | V12: =U12/H12/Assumptions!$E$21 -> -0.3490625 | W12: =R12/H12 -> 0
A13: ACREX | B13: Acrex | D13: 370 | E13: ACREX 2025 | F13: Paid | G13: 83129 | H13: 79 | I13: 1052.2658 | J13: 88 | K13: 1.1139241 | L13: 37 | M13: 0.035162218 | N13: 335 | O13: 0.31836062 | P13: 1 | Q13: =H13*2 -> 158 | R13: =J13*Assumptions!$E$19 -> 22.88 | S13: =G13*Assumptions!$E$10*Assumptions!$E$6+J13*Assumptions!$E$7+M13*Assumptions!$E$13*Assumptions!$E$6+N13*Assumptions!$E$12*Assumptions!$E$6+Q13*Assumptions!$E$15*Assumptions!$E$6 -> 47520.321 | T13: =R13*Assumptions!$E$20-H13*Assumptions!$E$21 -> 7080 | U13: =T13+S13 -> 54600.321 | V13: =U13/H13/Assumptions!$E$21 -> 3.4557165 | W13: =R13/H13 -> 0.28962025
A14: Amanat | B14: BNI | D14: 309 | E14: BBC Social Champ Contest | F14: Paid | G14: 82580 | H14: 30 | I14: 2752.6667 | J14: 44 | K14: 1.4666667 | L14: 12 | M14: 0.0043594091 | N14: 72 | O14: 0.026156454 | P14: 2 | Q14: =H14*2 -> 60 | R14: =J14*Assumptions!$E$19 -> 11.44 | S14: =G14*Assumptions!$E$10*Assumptions!$E$6+J14*Assumptions!$E$7+M14*Assumptions!$E$13*Assumptions!$E$6+N14*Assumptions!$E$12*Assumptions!$E$6+Q14*Assumptions!$E$15*Assumptions!$E$6 -> 22985.468 | T14: =R14*Assumptions!$E$20-H14*Assumptions!$E$21 -> 5440 | U14: =T14+S14 -> 28425.468 | V14: =U14/H14/Assumptions!$E$21 -> 4.737578 | W14: =R14/H14 -> 0.38133333
A15: Amanat | B15: BNI | D15: 339 | E15: BNI Conclave Live | F15: Paid | G15: 52308 | H15: 16 | I15: 3269.25 | J15: 26 | K15: 1.625 | L15: 19 | M15: 0.0058117305 | N15: 69 | O15: 0.021105758 | P15: 1 | Q15: =H15*2 -> 32 | R15: =J15*Assumptions!$E$19 -> 6.76 | S15: =G15*Assumptions!$E$10*Assumptions!$E$6+J15*Assumptions!$E$7+M15*Assumptions!$E$13*Assumptions!$E$6+N15*Assumptions!$E$12*Assumptions!$E$6+Q15*Assumptions!$E$15*Assumptions!$E$6 -> 14290.541 | T15: =R15*Assumptions!$E$20-H15*Assumptions!$E$21 -> 3560 | U15: =T15+S15 -> 17850.541 | V15: =U15/H15/Assumptions!$E$21 -> 5.5782939 | W15: =R15/H15 -> 0.4225
A16: Amrit Mishra | B16: Pangea Tech | D16: 322 | E16: Pangea Tech Social Champ | F16: Free | G16: 10538 | H16: 10 | I16: 1053.8 | J16: 0 | K16: 0 | L16: 4 | M16: 0.0037957867 | N16: 54 | O16: 0.05124312 | P16: 1 | Q16: =H16*2 -> 20 | R16: =J16*Assumptions!$E$19 -> 0 | S16: =G16*Assumptions!$E$10*Assumptions!$E$6+J16*Assumptions!$E$7+M16*Assumptions!$E$13*Assumptions!$E$6+N16*Assumptions!$E$12*Assumptions!$E$6+Q16*Assumptions!$E$15*Assumptions!$E$6 -> 3008.8148 | T16: =R16*Assumptions!$E$20-H16*Assumptions!$E$21 -> -2000 | U16: =T16+S16 -> 1008.8148 | V16: =U16/H16/Assumptions!$E$21 -> 0.50440739 | W16: =R16/H16 -> 0
A17: Atrayee Dutta | B17: Commvault | D17: 182 | E17: Commvault Partner Bootcamp, Bangalore | F17: Paid | G17: 41814 | H17: 124 | I17: 337.20968 | J17: 133 | K17: 1.0725806 | L17: 20 | M17: 0.059310279 | N17: 1357 | O17: 4.0242024 | P17: 6 | Q17: =H17*2 -> 248 | R17: =J17*Assumptions!$E$19 -> 34.58 | S17: =G17*Assumptions!$E$10*Assumptions!$E$6+J17*Assumptions!$E$7+M17*Assumptions!$E$13*Assumptions!$E$6+N17*Assumptions!$E$12*Assumptions!$E$6+Q17*Assumptions!$E$15*Assumptions!$E$6 -> 88309.341 | T17: =R17*Assumptions!$E$20-H17*Assumptions!$E$21 -> 9780 | U17: =T17+S17 -> 98089.341 | V17: =U17/H17/Assumptions!$E$21 -> 3.9552153 | W17: =R17/H17 -> 0.27887097
A18: Chaitra Vedullapalli | B18: WIC | D18: 86 | E18: WICxCybersecurity Initative | F18: Trial | G18: 369041 | H18: 275 | I18: 1341.9673 | J18: 3559 | K18: 12.941818 | L18: 1074 | M18: 0.80031758 | N18: 5584 | O18: 4.1610553 | P18: 2 | Q18: =H18*2 -> 550 | R18: =J18*Assumptions!$E$19 -> 925.34 | S18: =G18*Assumptions!$E$10*Assumptions!$E$6+J18*Assumptions!$E$7+M18*Assumptions!$E$13*Assumptions!$E$6+N18*Assumptions!$E$12*Assumptions!$E$6+Q18*Assumptions!$E$15*Assumptions!$E$6 -> 1243669.1 | T18: =R18*Assumptions!$E$20-H18*Assumptions!$E$21 -> 870340 | U18: =T18+S18 -> 2114009.1 | V18: =U18/H18/Assumptions!$E$21 -> 38.436529 | W18: =R18/H18 -> 3.3648727
... A41: Devashish Sharma | B41: Salesforce | D41: 211 | E41: Salesforce Social Champ Contest | F41: Paid | G41: 230813 | H41: 131 | I41: 1761.9313 | J41: 90 | K41: 0.6870229 | L41: 17 | M41: 0.0096485033 | N41: 1691 | O41: 0.9597423 | P41: 9 | Q41: =H41*2 -> 262 | R41: =J41*Assumptions!$E$19 -> 23.4 | S41: =G41*Assumptions!$E$10*Assumptions!$E$6+J41*Assumptions!$E$7+M41*Assumptions!$E$13*Assumptions!$E$6+N41*Assumptions!$E$12*Assumptions!$E$6+Q41*Assumptions!$E$15*Assumptions!$E$6 -> 96441.295 | T41: =R41*Assumptions!$E$20-H41*Assumptions!$E$21 -> -2800 | U41: =T41+S41 -> 93641.295 | V41: =U41/H41/Assumptions!$E$21 -> 3.5740952 | W41: =R41/H41 -> 0.17862595
A42: Himanshu Keystone | B42: Salesforce | C42: Keystone | D42: 336 | E42: AI Summit 28 Feb | F42: Paid | G42: 4785277 | H42: 2932 | I42: 1632.0863 | J42: 12107 | K42: 4.1292633 | L42: 4003 | M42: 2.4526889 | N42: 20196 | O42: 12.374346 | P42: 4 | Q42: =H42*2 -> 5864 | R42: =J42*Assumptions!$E$19 -> 3147.82 | S42: =G42*Assumptions!$E$10*Assumptions!$E$6+J42*Assumptions!$E$7+M42*Assumptions!$E$13*Assumptions!$E$6+N42*Assumptions!$E$12*Assumptions!$E$6+Q42*Assumptions!$E$15*Assumptions!$E$6 -> 4680974.4 | T42: =R42*Assumptions!$E$20-H42*Assumptions!$E$21 -> 2561420 | U42: =T42+S42 -> 7242394.4 | V42: =U42/H42/Assumptions!$E$21 -> 12.350604 | W42: =R42/H42 -> 1.0736085
A43: Himanshu Keystone | B43: Salesforce | C43: Keystone | D43: 318 | E43: Salesforce Industries Virtual Summit 2024 - Live | F43: Paid | G43: 691286 | H43: 348 | I43: 1986.454 | J43: 951 | K43: 2.7327586 | L43: 30 | M43: 0.015102288 | N43: 1961 | O43: 0.9871862 | P43: 1 | Q43: =H43*2 -> 696 | R43: =J43*Assumptions!$E$19 -> 247.26 | S43: =G43*Assumptions!$E$10*Assumptions!$E$6+J43*Assumptions!$E$7+M43*Assumptions!$E$13*Assumptions!$E$6+N43*Assumptions!$E$12*Assumptions!$E$6+Q43*Assumptions!$E$15*Assumptions!$E$6 -> 408527.13 | T43: =R43*Assumptions!$E$20-H43*Assumptions!$E$21 -> 177660 | U43: =T43+S43 -> 586187.13 | V43: =U43/H43/Assumptions!$E$21 -> 8.4222289 | W43: =R43/H43 -> 0.71051724
A44: Himanshu Keystone | B44: Salesforce | C44: Keystone | D44: 271 | E44: Salesforce Great India Growth Summit | F44: Paid | G44: 483180 | H44: 286 | I44: 1689.4406 | J44: 928 | K44: 3.2447552 | L44: 50 | M44: 0.029595596 | N44: 2420 | O44: 1.4324268 | P44: 1 | Q44: =H44*2 -> 572 | R44: =J44*Assumptions!$E$19 -> 241.28 | S44: =G44*Assumptions!$E$10*Assumptions!$E$6+J44*Assumptions!$E$7+M44*Assumptions!$E$13*Assumptions!$E$6+N44*Assumptions!$E$12*Assumptions!$E$6+Q44*Assumptions!$E$15*Assumptions!$E$6 -> 393988.23 | T44: =R44*Assumptions!$E$20-H44*Assumptions!$E$21 -> 184080 | U44: =T44+S44 -> 578068.23 | V44: =U44/H44/Assumptions!$E$21 -> 10.106088 | W44: =R44/H44 -> 0.84363636
A45: Himanshu Keystone | B45: Salesforce | C45: Keystone | D45: 241 | E45: Salesforce AI Virtual Summit - 2024 | F45: Paid | G45: 337976 | H45: 201 | I45: 1681.4726 | J45: 1129 | K45: 5.6169154 | L45: 30 | M45: 0.017841504 | N45: 2084 | O45: 1.2393898 | P45: 1 | Q45: =H45*2 -> 402 | R45: =J45*Assumptions!$E$19 -> 293.54 | S45: =G45*Assumptions!$E$10*Assumptions!$E$6+J45*Assumptions!$E$7+M45*Assumptions!$E$13*Assumptions!$E$6+N45*Assumptions!$E$12*Assumptions!$E$6+Q45*Assumptions!$E$15*Assumptions!$E$6 -> 427508.39 | T45: =R45*Assumptions!$E$20-H45*Assumptions!$E$21 -> 253340 | U45: =T45+S45 -> 680848.39 | V45: =U45/H45/Assumptions!$E$21 -> 16.936527 | W45: =R45/H45 -> 1.460398
A46: Himanshu Keystone | B46: Salesforce | C46: Keystone | D46: 319 | E46: Salesforce Industries Virtual Summit 2024 - Live | F46: Paid | G46: 381506 | H46: 191 | I46: 1997.4136 | J46: 898 | K46: 4.7015707 | L46: 376 | M46: 0.18824344 | N46: 1402 | O46: 0.7019077 | P46: 1 | Q46: =H46*2 -> 382 | R46: =J46*Assumptions!$E$19 -> 233.48 | S46: =G46*Assumptions!$E$10*Assumptions!$E$6+J46*Assumptions!$E$7+M46*Assumptions!$E$13*Assumptions!$E$6+N46*Assumptions!$E$12*Assumptions!$E$6+Q46*Assumptions!$E$15*Assumptions!$E$6 -> 343811.54 | T46: =R46*Assumptions!$E$20-H46*Assumptions!$E$21 -> 195280 | U46: =T46+S46 -> 539091.54 | V46: =U46/H46/Assumptions!$E$21 -> 14.112344 | W46: =R46/H46 -> 1.2224084
A47: Himanshu Keystone | B47: Salesforce | C47: Keystone | D47: 244 | E47: Great India Growth Summit WA | F47: Paid | G47: 193844 | H47: 131 | I47: 1479.7252 | J47: 339 | K47: 2.5877863 | L47: 25 | M47: 0.016895029 | N47: 522 | O47: 0.35276821 | P47: 1 | Q47: =H47*2 -> 262 | R47: =J47*Assumptions!$E$19 -> 88.14 | S47: =G47*Assumptions!$E$10*Assumptions!$E$6+J47*Assumptions!$E$7+M47*Assumptions!$E$13*Assumptions!$E$6+N47*Assumptions!$E$12*Assumptions!$E$6+Q47*Assumptions!$E$15*Assumptions!$E$6 -> 138610.09 | T47: =R47*Assumptions!$E$20-H47*Assumptions!$E$21 -> 61940 | U47: =T47+S47 -> 200550.09 | V47: =U47/H47/Assumptions!$E$21 -> 7.6545838 | W47: =R47/H47 -> 0.67282443
A48: Himanshu Keystone | B48: Salesforce | C48: Keystone | D48: 307 | E48: Salesforce Industries Virtual Summit 2024 | F48: Paid | G48: 244919 | H48: 110 | I48: 2226.5364 | J48: 769 | K48: 6.9909091 | L48: 34 | M48: 0.015270355 | N48: 783 | O48: 0.35166729 | P48: 1 | Q48: =H48*2 -> 220 | R48: =J48*Assumptions!$E$19 -> 199.94 | S48: =G48*Assumptions!$E$10*Assumptions!$E$6+J48*Assumptions!$E$7+M48*Assumptions!$E$13*Assumptions!$E$6+N48*Assumptions!$E$12*Assumptions!$E$6+Q48*Assumptions!$E$15*Assumptions!$E$6 -> 273507.2 | T48: =R48*Assumptions!$E$20-H48*Assumptions!$E$21 -> 177940 | U48: =T48+S48 -> 451447.2 | V48: =U48/H48/Assumptions!$E$21 -> 20.520327 | W48: =R48/H48 -> 1.8176364
A49: Himanshu Keystone | B49: Salesforce | C49: Keystone | D49: 328 | E49: Salesforce Trailblazer Thursdays | F49: Trial | G49: 19372 | H49: 8 | I49: 2421.5 | J49: 35 | K49: 4.375 | L49: 2 | M49: 0.00082593434 | N49: 64 | O49: 0.026429899 | P49: 2 | Q49: =H49*2 -> 16 | R49: =J49*Assumptions!$E$19 -> 9.1 | S49: =G49*Assumptions!$E$10*Assumptions!$E$6+J49*Assumptions!$E$7+M49*Assumptions!$E$13*Assumptions!$E$6+N49*Assumptions!$E$12*Assumptions!$E$6+Q49*Assumptions!$E$15*Assumptions!$E$6 -> 13970.791 | T49: =R49*Assumptions!$E$20-H49*Assumptions!$E$21 -> 7500 | U49: =T49+S49 -> 21470.791 | V49: =U49/H49/Assumptions!$E$21 -> 13.419245 | W49: =R49/H49 -> 1.1375
A50: Kailash Ahuja | B50: Dell | D50: 378 | E50: Coffee With Dell - 07 March | F50: Trial | G50: 2462 | H50: 4 | I50: 615.5 | J50: 2 | K50: 0.5 | L50: 0 | M50: 0 | N50: 0 | O50: 0 | P50: 1 | Q50: =H50*2 -> 8 | R50: =J50*Assumptions!$E$19 -> 0.52 | S50: =G50*Assumptions!$E$10*Assumptions!$E$6+J50*Assumptions!$E$7+M50*Assumptions!$E$13*Assumptions!$E$6+N50*Assumptions!$E$12*Assumptions!$E$6+Q50*Assumptions!$E$15*Assumptions!$E$6 -> 1145.875 | T50: =R50*Assumptions!$E$20-H50*Assumptions!$E$21 -> -280 | U50: =T50+S50 -> 865.875 | V50: =U50/H50/Assumptions!$E$21 -> 1.0823437 | W50: =R50/H50 -> 0.13
A51: Kamanashish Roy | B51: Salesforce | D51: 113 | E51: Salesforce GSS | F51: Paid | G51: 773072 | H51: 341 | I51: 2267.0733 | J51: 1963 | K51: 5.7565982 | L51: 49 | M51: 0.021613769 | N51: 3389 | O51: 1.4948789 | P51: 2 | Q51: =H51*2 -> 682 | R51: =J51*Assumptions!$E$19 -> 510.38 | S51: =G51*Assumptions!$E$10*Assumptions!$E$6+J51*Assumptions!$E$7+M51*Assumptions!$E$13*Assumptions!$E$6+N51*Assumptions!$E$12*Assumptions!$E$6+Q51*Assumptions!$E$15*Assumptions!$E$6 -> 748191.08 | T51: =R51*Assumptions!$E$20-H51*Assumptions!$E$21 -> 442180 | U51: =T51+S51 -> 1190371.1 | V51: =U51/H51/Assumptions!$E$21 -> 17.454121 | W51: =R51/H51 -> 1.4967155
A52: Kamanashish Roy | B52: Salesforce | D52: 195 | E52: Great India Growth Summit | F52: Paid | G52: 768141 | H52: 323 | I52: 2378.1455 | J52: 1155 | K52: 3.5758514 | L52: 18 | M52: 0.0075689229 | N52: 1152 | O52: 0.48441107 | P52: 1 | Q52: =H52*2 -> 646 | R52: =J52*Assumptions!$E$19 -> 300.3 | S52: =G52*Assumptions!$E$10*Assumptions!$E$6+J52*Assumptions!$E$7+M52*Assumptions!$E$13*Assumptions!$E$6+N52*Assumptions!$E$12*Assumptions!$E$6+Q52*Assumptions!$E$15*Assumptions!$E$6 -> 450989.19 | T52: =R52*Assumptions!$E$20-H52*Assumptions!$E$21 -> 235700 | U52: =T52+S52 -> 686689.19 | V52: =U52/H52/Assumptions!$E$21 -> 10.629864 | W52: =R52/H52 -> 0.92972136
A53: Kamanashish Roy | B53: HPE | D53: 291 | E53: HPE NVIDIA AI Summit | F53: Paid | G53: 299074 | H53: 279 | I53: 1071.9498 | J53: 786 | K53: 2.8172043 | L53: 25 | M53: 0.023321987 | N53: 3379 | O53: 3.1521998 | P53: 4 | Q53: =H53*2 -> 558 | R53: =J53*Assumptions!$E$19 -> 204.36 | S53: =G53*Assumptions!$E$10*Assumptions!$E$6+J53*Assumptions!$E$7+M53*Assumptions!$E$13*Assumptions!$E$6+N53*Assumptions!$E$12*Assumptions!$E$6+Q53*Assumptions!$E$15*Assumptions!$E$6 -> 363724.29 | T53: =R53*Assumptions!$E$20-H53*Assumptions!$E$21 -> 148560 | U53: =T53+S53 -> 512284.29 | V53: =U53/H53/Assumptions!$E$21 -> 9.1807221 | W53: =R53/H53 -> 0.73247312
A54: Kamanashish Roy | B54: Salesforce | D54: 209 | E54: Salesforce AI Virtual Summit | F54: Paid | G54: 241861 | H54: 87 | I54: 2780.0115 | J54: 748 | K54: 8.5977011 | L54: 15 | M54: 0.0053956611 | N54: 1200 | O54: 0.43165289 | P54: 1 | Q54: =H54*2 -> 174 | R54: =J54*Assumptions!$E$19 -> 194.48 | S54: =G54*Assumptions!$E$10*Assumptions!$E$6+J54*Assumptions!$E$7+M54*Assumptions!$E$13*Assumptions!$E$6+N54*Assumptions!$E$12*Assumptions!$E$6+Q54*Assumptions!$E$15*Assumptions!$E$6 -> 275224.58 | T54: =R54*Assumptions!$E$20-H54*Assumptions!$E$21 -> 177080 | U54: =T54+S54 -> 452304.58 | V54: =U54/H54/Assumptions!$E$21 -> 25.994516 | W54: =R54/H54 -> 2.2354023
A55: Kamanashish Roy | B55: MicroGenesis | D55: 192 | E55: MicroGenesis Executive Connect: Shaping the Future of the AEC Industry | F55: Paid | G55: 65368 | H55: 50 | I55: 1307.36 | J55: 25 | K55: 0.5 | L55: 16 | M55: 0.012238404 | N55: 709 | O55: 0.54231428 | P55: 5 | Q55: =H55*2 -> 100 | R55: =J55*Assumptions!$E$19 -> 6.5 | S55: =G55*Assumptions!$E$10*Assumptions!$E$6+J55*Assumptions!$E$7+M55*Assumptions!$E$13*Assumptions!$E$6+N55*Assumptions!$E$12*Assumptions!$E$6+Q55*Assumptions!$E$15*Assumptions!$E$6 -> 34211.112 | T55: =R55*Assumptions!$E$20-H55*Assumptions!$E$21 -> -3500 | U55: =T55+S55 -> 30711.112 | V55: =U55/H55/Assumptions!$E$21 -> 3.0711112 | W55: =R55/H55 -> 0.13
A56: Kamanashish Roy | B56: Kyndryl | D56: 102 | E56: Kyndryl | F56: Trial | G56: 51924 | H56: 32 | I56: 1622.625 | J56: 0 | K56: 0 | L56: 38 | M56: 0.023418843 | N56: 1040 | O56: 0.64093675 | P56: 2 | Q56: =H56*2 -> 64 | R56: =J56*Assumptions!$E$19 -> 0 | S56: =G56*Assumptions!$E$10*Assumptions!$E$6+J56*Assumptions!$E$7+M56*Assumptions!$E$13*Assumptions!$E$6+N56*Assumptions!$E$12*Assumptions!$E$6+Q56*Assumptions!$E$15*Assumptions!$E$6 -> 32446.421 | T56: =R56*Assumptions!$E$20-H56*Assumptions!$E$21 -> -6400 | U56: =T56+S56 -> 26046.421 | V56: =U56/H56/Assumptions!$E$21 -> 4.0697533 | W56: =R56/H56 -> 0
A57: Kamanashish Roy | B57: Salesforce | D57: 215 | E57: State Of Sales | F57: Trial | G57: 86416 | H57: 32 | I57: 2700.5 | J57: 241 | K57: 7.53125 | L57: 5 | M57: 0.001851509 | N57: 329 | O57: 0.12182929 | P57: 1 | Q57: =H57*2 -> 64 | R57: =J57*Assumptions!$E$19 -> 62.66 | S57: =G57*Assumptions!$E$10*Assumptions!$E$6+J57*Assumptions!$E$7+M57*Assumptions!$E$13*Assumptions!$E$6+N57*Assumptions!$E$12*Assumptions!$E$6+Q57*Assumptions!$E$15*Assumptions!$E$6 -> 88162.093 | T57: =R57*Assumptions!$E$20-H57*Assumptions!$E$21 -> 56260 | U57: =T57+S57 -> 144422.09 | V57: =U57/H57/Assumptions!$E$21 -> 22.565952 | W57: =R57/H57 -> 1.958125
A58: Kamanashish Roy | B58: Atria | D58: 110 | E58: State Level Project Exhibition 2024 - Live | F58: Trial | G58: 0 | H58: 29 | I58: 0 | J58: 0 | K58: 0 | L58: 4 | M58: 0 | N58: 139 | O58: 0 | P58: 1 | Q58: =H58*2 -> 58 | R58: =J58*Assumptions!$E$19 -> 0 | S58: =G58*Assumptions!$E$10*Assumptions!$E$6+J58*Assumptions!$E$7+M58*Assumptions!$E$13*Assumptions!$E$6+N58*Assumptions!$E$12*Assumptions!$E$6+Q58*Assumptions!$E$15*Assumptions!$E$6 -> 6375 | T58: =R58*Assumptions!$E$20-H58*Assumptions!$E$21 -> -5800 | U58: =T58+S58 -> 575 | V58: =U58/H58/Assumptions!$E$21 -> 0.099137931 | W58: =R58/H58 -> 0
A59: Kamanashish Roy | B59: Atria | D59: 109 | E59: Atria Alumni | F59: Trial | G59: 0 | H59: 24 | I59: 0 | J59: 0 | K59: 0 | L59: 5 | M59: 0 | N59: 232 | O59: 0 | P59: 5 | Q59: =H59*2 -> 48 | R59: =J59*Assumptions!$E$19 -> 0 | S59: =G59*Assumptions!$E$10*Assumptions!$E$6+J59*Assumptions!$E$7+M59*Assumptions!$E$13*Assumptions!$E$6+N59*Assumptions!$E$12*Assumptions!$E$6+Q59*Assumptions!$E$15*Assumptions!$E$6 -> 8200 | T59: =R59*Assumptions!$E$20-H59*Assumptions!$E$21 -> -4800 | U59: =T59+S59 -> 3400 | V59: =U59/H59/Assumptions!$E$21 -> 0.70833333 | W59: =R59/H59 -> 0
A60: karthik | B60: Red Hat | D60: 281 | E60: Red Hat Summit: Connect 2024 Live | F60: Paid | G60: 176131 | H60: 1196 | I60: 147.26672 | J60: 517 | K60: 0.43227425 | L60: 41 | M60: 0.27840641 | N60: 3863 | O60: 26.231316 | P60: 10 | Q60: =H60*2 -> 2392 | R60: =J60*Assumptions!$E$19 -> 134.42 | S60: =G60*Assumptions!$E$10*Assumptions!$E$6+J60*Assumptions!$E$7+M60*Assumptions!$E$13*Assumptions!$E$6+N60*Assumptions!$E$12*Assumptions!$E$6+Q60*Assumptions!$E$15*Assumptions!$E$6 -> 380229.11 | T60: =R60*Assumptions!$E$20-H60*Assumptions!$E$21 -> -104780 | U60: =T60+S60 -> 275449.11 | V60: =U60/H60/Assumptions!$E$21 -> 1.1515431 | W60: =R60/H60 -> 0.1123913
A61: karthik | B61: Red Hat | D61: 153 | E61: Red Hat Ansible Automates Live | F61: Paid | G61: 205216 | H61: 434 | I61: 472.84793 | J61: 1185 | K61: 2.7304147 | L61: 195 | M61: 0.41239475 | N61: 2823 | O61: 5.970207 | P61: 9 | Q61: =H61*2 -> 868 | R61: =J61*Assumptions!$E$19 -> 308.1 | S61: =G61*Assumptions!$E$10*Assumptions!$E$6+J61*Assumptions!$E$7+M61*Assumptions!$E$13*Assumptions!$E$6+N61*Assumptions!$E$12*Assumptions!$E$6+Q61*Assumptions!$E$15*Assumptions!$E$6 -> 477581.62 | T61: =R61*Assumptions!$E$20-H61*Assumptions!$E$21 -> 221300 | U61: =T61+S61 -> 698881.62 | V61: =U61/H61/Assumptions!$E$21 -> 8.0516316 | W61: =R61/H61 -> 0.70990783
... A147: Praveen Kumar Soma | B147: CII | D147: 216 | E147: CII Greenpro Summit 2024 | F147: Paid | G147: 29358 | H147: 25 | I147: 1174.32 | J147: 58 | K147: 2.32 | L147: 18 | M147: 0.01532802 | N147: 437 | O147: 0.37213025 | P147: 15 | Q147: =H147*2 -> 50 | R147: =J147*Assumptions!$E$19 -> 15.08 | S147: =G147*Assumptions!$E$10*Assumptions!$E$6+J147*Assumptions!$E$7+M147*Assumptions!$E$13*Assumptions!$E$6+N147*Assumptions!$E$12*Assumptions!$E$6+Q147*Assumptions!$E$15*Assumptions!$E$6 -> 32428.641 | T147: =R147*Assumptions!$E$20-H147*Assumptions!$E$21 -> 10080 | U147: =T147+S147 -> 42508.641 | V147: =U147/H147/Assumptions!$E$21 -> 8.5017283 | W147: =R147/H147 -> 0.6032
...

Sheet Sheet2
A1: campaign_id | B1: Customer Name | C1: Company | D1: campaign_title | E1: Paid or not | F1: total_share | G1: Reach per Share | H1: total_clicks | I1: Clicks per Share | J1: total_comments | K1: Comments Per Share | L1: total_likes | M1: Likes Per Share | N1: No.of post created | O1: No. of Form Submissiom | P1: EMV | Q1: Direct Savings | R1: Total Return | S1: ROI (in X)

Sheet Pivot Table 2

Sheet Pivot Table 1

Sheet Assumptions
D5: How much are you spending for | E5: In INR | G5: Reasons
D6: Cost Per Impression | E6: 0.5 | G6: Avg Industry CMP on LinkedIn in India is Rs 500, hence for each impression it is .50p
D7: Cost Per Click | E7: 296 | G7: Avg Industry CPC on LInkedIn in India is Rs 160. CPC can vary drastically and go up to Rs 2000 to Rs 5000 in some cases.
E9: Impression Multiplier | F9: Sample Data from One Campaign
D10: Potential Impression | E10: 0.125 | F10: 4780994 | G10: Any post that goes out is assumed to have a 12%-15% visibilty from the follower newtwork of any profile. The Potential Impression in "sample data" column is the sum of followers that the participants who shared a post have. Consider this: If a participant has 1000 followers and he shares a post, he would get 120 to 150 impression on his post (12%-15% of total followers).
D11: Clicks | E11: 1 | F11: 12135 | G11: Clicks is the count of number of people who clicked on any link that is there in the post. In few cases where there is no link in the post, there would be no click data for that campaign. It is worth noting that each click further amplifies a post but for the sake of calculation, impressions from clicks are not considered for EMV calculation rather CPC is considered.
D12: Reactions (Likes) | E12: 50 | F12: 20431 | G12: For each reaction that someone gets on his post, it is assumed at least 5% of his own followers and a fraction of people in the network of the person who liked the post will receive the post in their feed.
D13: Comments | E13: 100 | F13: 4000 | G13: For each comment that someone gets on his post, it is assumed at least 10% of his own followers and a fraction of people in the network of the person who commented on the post will receive the post in their feed.
D14: Shares | E14: 0 | F14: 2932
D15: Reshares | E15: 100 | F15: =F14*2 -> 5864 | G15: It is assumed that each post will get at least 2 more shares, gathering 100 more impressions each.
D17: EMV | E17: =E10*F10*E6+E11*F11*E7+E12*F12*E6+E13*F13*E6+E15*F14*E6 -> 4748147.1
D19: Click2Registration | E19: 0.26 | G19: Based on all the campaigns ever run through Wozku, Avg C2R is 26%.
D20: Cost per Registration | E20: 1000 | G20: This is the minimum cost any client spends to get one registration for their physical/virtual event.
D21: Cost per Share | E21: 200 | G21: This is the cost of consuming one share on Wozku.

Sheet Copy of Assumptions
D5: How much are you spending for | E5: In INR | G5: Reasons
D6: Cost Per Impression | E6: 0.5 | G6: Avg Industry CMP on LinkedIn in India is Rs 500, hence for each impression it is .50p
D7: Cost Per Click | E7: 296 | G7: Avg Industry CPC on LInkedIn in India is Rs 160. CPC can vary drastically and go up to Rs 2000 to Rs 5000 in some cases.
E9: Impression Multiplier | F9: Sample Data from One Campaign
D10: Potential Impression | E10: 0.125 | F10: 13537927 | G10: Any post that goes out is assumed to have a 12%-15% visibilty from the follower newtwork of any profile. The Potential Impression in "sample data" column is the sum of followers that the participants who shared a post have. Consider this: If a participant has 1000 followers and he shares a post, he would get 120 to 150 impression on his post (12%-15% of total followers).
D11: Clicks | E11: 1 | F11: 31851 | G11: Clicks is the count of number of people who clicked on any link that is there in the post. In few cases where there is no link in the post, there would be no click data for that campaign. It is worth noting that each click further amplifies a post but for the sake of calculation, impressions from clicks are not considered for EMV calculation rather CPC is considered.
D12: Reactions (Likes) | E12: 50 | F12: 101693 | G12: For each reaction that someone gets on his post, it is assumed at least 5% of his own followers and a fraction of people in the network of the person who liked the post will receive the post in their feed.
D13: Comments | E13: 100 | F13: 23898 | G13: For each comment that someone gets on his post, it is assumed at least 10% of his own followers and a fraction of people in the network of the person who commented on the post will receive the post in their feed.
D14: Shares | E14: 0 | F14: 8914
D15: Reshares | E15: 100 | F15: =F14*2 -> 17828 | G15: It is assumed that each post will get at least 2 more shares, gathering 100 more impressions each.
D17: EMV | E17: =E10*F10*E6+E11*F11*E7+E12*F12*E6+E13*F13*E6+E15*F14*E6 -> 14456941
D19: Click2Registration | E19: 0.26 | G19: Based on all the campaigns ever run through Wozku, Avg C2R is 26%.
D20: Cost per Registration | E20: 1000 | G20: This is the minimum cost any client spends to get one registration for their physical/virtual event.
D21: Cost per Share | E21: 200 | G21: This is the cost of consuming one share on Wozku.
